{
 "cells": [
  {
   "cell_type": "code",
   "execution_count": 5,
   "metadata": {},
   "outputs": [],
   "source": [
    "import platform\n",
    "import sys\n",
    "\n",
    "is_win = \"windows\" in platform.platform().lower()"
   ]
  },
  {
   "cell_type": "code",
   "execution_count": 6,
   "metadata": {},
   "outputs": [
    {
     "data": {
      "text/plain": [
       "True"
      ]
     },
     "execution_count": 6,
     "metadata": {},
     "output_type": "execute_result"
    }
   ],
   "source": [
    "is_win"
   ]
  },
  {
   "cell_type": "code",
   "execution_count": 9,
   "metadata": {},
   "outputs": [
    {
     "name": "stderr",
     "output_type": "stream",
     "text": [
      "ERROR: Could not find a version that satisfies the requirement opencv-openvino-contrib-python (from versions: none)\n",
      "ERROR: No matching distribution found for opencv-openvino-contrib-python\n"
     ]
    }
   ],
   "source": [
    "!pip install opencv-openvino-contrib-python"
   ]
  },
  {
   "cell_type": "code",
   "execution_count": 10,
   "metadata": {},
   "outputs": [
    {
     "name": "stdout",
     "output_type": "stream",
     "text": [
      "Collecting opencv-contrib-python\n",
      "  Downloading opencv_contrib_python-4.3.0.36-cp36-cp36m-win_amd64.whl (40.0 MB)\n",
      "Requirement already satisfied: numpy>=1.11.3 in d:\\installation\\anaconda3\\envs\\automobile\\lib\\site-packages (from opencv-contrib-python) (1.18.5)\n",
      "Installing collected packages: opencv-contrib-python\n",
      "Successfully installed opencv-contrib-python-4.3.0.36\n"
     ]
    }
   ],
   "source": [
    "!pip install opencv-contrib-python"
   ]
  },
  {
   "cell_type": "code",
   "execution_count": 7,
   "metadata": {},
   "outputs": [
    {
     "name": "stderr",
     "output_type": "stream",
     "text": [
      "ERROR:root:Internal Python error in the inspect module.\n",
      "Below is the traceback from this internal error.\n",
      "\n"
     ]
    },
    {
     "name": "stdout",
     "output_type": "stream",
     "text": [
      "The following error happened while importing Python API module:\n",
      "[ ModuleNotFoundError ] No module named 'openvino'\n",
      "Traceback (most recent call last):\n",
      "  File \"<ipython-input-7-d42f3ed2c9a2>\", line 7, in <module>\n",
      "    from openvino import inference_engine as ie\n",
      "ModuleNotFoundError: No module named 'openvino'\n",
      "\n",
      "During handling of the above exception, another exception occurred:\n",
      "\n",
      "Traceback (most recent call last):\n",
      "  File \"D:\\Installation\\Anaconda3\\lib\\site-packages\\IPython\\core\\interactiveshell.py\", line 3331, in run_code\n",
      "    exec(code_obj, self.user_global_ns, self.user_ns)\n",
      "  File \"<ipython-input-7-d42f3ed2c9a2>\", line 16, in <module>\n",
      "    sys.exit(1)\n",
      "SystemExit: 1\n",
      "\n",
      "During handling of the above exception, another exception occurred:\n",
      "\n",
      "Traceback (most recent call last):\n",
      "  File \"D:\\Installation\\Anaconda3\\lib\\site-packages\\IPython\\core\\ultratb.py\", line 1148, in get_records\n",
      "    return _fixed_getinnerframes(etb, number_of_lines_of_context, tb_offset)\n",
      "  File \"D:\\Installation\\Anaconda3\\lib\\site-packages\\IPython\\core\\ultratb.py\", line 316, in wrapped\n",
      "    return f(*args, **kwargs)\n",
      "  File \"D:\\Installation\\Anaconda3\\lib\\site-packages\\IPython\\core\\ultratb.py\", line 350, in _fixed_getinnerframes\n",
      "    records = fix_frame_records_filenames(inspect.getinnerframes(etb, context))\n",
      "  File \"D:\\Installation\\Anaconda3\\lib\\inspect.py\", line 1502, in getinnerframes\n",
      "    frameinfo = (tb.tb_frame,) + getframeinfo(tb, context)\n",
      "AttributeError: 'tuple' object has no attribute 'tb_frame'\n"
     ]
    },
    {
     "ename": "SystemExit",
     "evalue": "1",
     "output_type": "error",
     "traceback": [
      "An exception has occurred, use %tb to see the full traceback.\n",
      "\u001b[1;31m---------------------------------------------------------------------------\u001b[0m",
      "\nDuring handling of the above exception, another exception occurred:\n",
      "\u001b[1;31mSystemExit\u001b[0m\u001b[1;31m:\u001b[0m 1\n"
     ]
    },
    {
     "name": "stderr",
     "output_type": "stream",
     "text": [
      "D:\\Installation\\Anaconda3\\lib\\site-packages\\IPython\\core\\interactiveshell.py:3339: UserWarning: To exit: use 'exit', 'quit', or Ctrl-D.\n",
      "  warn(\"To exit: use 'exit', 'quit', or Ctrl-D.\", stacklevel=1)\n"
     ]
    }
   ],
   "source": [
    "if is_win:\n",
    "    message = 'Please run \"F:\\Program Files (x86)\\IntelSWTools\\openvino_2020.4.287\\bin\\setupvars.bat\" before running this.'\n",
    "else:\n",
    "    message = \"Add the following line to ~/.bashrc and re-run.\\nsource /opt/intel/openvino/bin/setupvars.sh\"\n",
    "\n",
    "try:\n",
    "    from openvino import inference_engine as ie\n",
    "    from openvino.inference_engine import IENetwork, IEPlugin\n",
    "except Exception as e:\n",
    "    exception_type = type(e).__name__\n",
    "    print(\n",
    "        \"The following error happened while importing Python API module:\\n[ {} ] {}\".format(\n",
    "            exception_type, e\n",
    "        )\n",
    "    )\n",
    "    sys.exit(1)"
   ]
  },
  {
   "cell_type": "code",
   "execution_count": null,
   "metadata": {},
   "outputs": [],
   "source": []
  }
 ],
 "metadata": {
  "kernelspec": {
   "display_name": "Python 3",
   "language": "python",
   "name": "python3"
  },
  "language_info": {
   "codemirror_mode": {
    "name": "ipython",
    "version": 3
   },
   "file_extension": ".py",
   "mimetype": "text/x-python",
   "name": "python",
   "nbconvert_exporter": "python",
   "pygments_lexer": "ipython3",
   "version": "3.7.4"
  }
 },
 "nbformat": 4,
 "nbformat_minor": 4
}
